Workbook

Sheet 八景汇总
A1: 消融记录：八场景汇总
A2: Replica 8 场景，每景 400 帧；固定 unified_fullmesh_v2_20260910。所有比率以百分数显示。
A4: 方法 | B4: 场景数 | C4: 实例 mIoU 每GT最佳 | D4: 实例 AP25 | E4: 实例 AP50 | F4: 实例 AP75 | G4: 语义 mIoU | H4: 语义 AP25 | I4: 语义 AP50 | J4: mAcc | K4: 物体覆盖率 5cm
A5: A ali-my baseline | B5: 8 | C5: 0.34565472 | D5: 0.4910127 | E5: 0.1879618 | F5: 0.017460089 | G5: 0.12117199 | H5: 0.17078768 | I5: 0.14210355 | J5: 0.24674136 | K5: 0.63509918
A6: B baseline＋原图 | B6: 8 | C6: 0.42589508 | D6: 0.59878792 | E6: 0.24236777 | F6: 0.044001228 | G6: 0.12517583 | H6: 0.21648877 | I6: 0.15410447 | J6: 0.26132565 | K6: 0.70640982
A7: C baseline＋原图＋CLIP | B7: 8 | C7: 0.42782932 | D7: 0.60084572 | E7: 0.25875964 | F7: 0.047850001 | G7: 0.12774026 | H7: 0.2017414 | I7: 0.13427807 | J7: 0.2406253 | K7: 0.70638804
A9: 相邻消融增益：正值为改善，负值为退化，单位为百分点。
A10: 增益比较 | B10: 场景数 | C10: 实例 mIoU 每GT最佳 | D10: 实例 AP25 | E10: 实例 AP50 | F10: 实例 AP75 | G10: 语义 mIoU | H10: 语义 AP25 | I10: 语义 AP50 | J10: mAcc | K10: 物体覆盖率 5cm
A11: B − A：原图输入 | B11: 8 | C11: =IF(AND(ISNUMBER(C6),ISNUMBER(C5)),(C6-C5)*100,"") -> 8.0240368 | D11: =IF(AND(ISNUMBER(D6),ISNUMBER(D5)),(D6-D5)*100,"") -> 10.777522 | E11: =IF(AND(ISNUMBER(E6),ISNUMBER(E5)),(E6-E5)*100,"") -> 5.4405972 | F11: =IF(AND(ISNUMBER(F6),ISNUMBER(F5)),(F6-F5)*100,"") -> 2.6541139 | G11: =IF(AND(ISNUMBER(G6),ISNUMBER(G5)),(G6-G5)*100,"") -> 0.40038426 | H11: =IF(AND(ISNUMBER(H6),ISNUMBER(H5)),(H6-H5)*100,"") -> 4.5701093 | I11: =IF(AND(ISNUMBER(I6),ISNUMBER(I5)),(I6-I5)*100,"") -> 1.2000921 | J11: =IF(AND(ISNUMBER(J6),ISNUMBER(J5)),(J6-J5)*100,"") -> 1.4584289 | K11: =IF(AND(ISNUMBER(K6),ISNUMBER(K5)),(K6-K5)*100,"") -> 7.1310642
A12: C − B：CLIP改进 | B12: 8 | C12: =IF(AND(ISNUMBER(C7),ISNUMBER(C6)),(C7-C6)*100,"") -> 0.19342334 | D12: =IF(AND(ISNUMBER(D7),ISNUMBER(D6)),(D7-D6)*100,"") -> 0.20577985 | E12: =IF(AND(ISNUMBER(E7),ISNUMBER(E6)),(E7-E6)*100,"") -> 1.6391865 | F12: =IF(AND(ISNUMBER(F7),ISNUMBER(F6)),(F7-F6)*100,"") -> 0.38487734 | G12: =IF(AND(ISNUMBER(G7),ISNUMBER(G6)),(G7-G6)*100,"") -> 0.25644232 | H12: =IF(AND(ISNUMBER(H7),ISNUMBER(H6)),(H7-H6)*100,"") -> -1.4747367 | I12: =IF(AND(ISNUMBER(I7),ISNUMBER(I6)),(I7-I6)*100,"") -> -1.9826403 | J12: =IF(AND(ISNUMBER(J7),ISNUMBER(J6)),(J7-J6)*100,"") -> -2.0700351 | K12: =IF(AND(ISNUMBER(K7),ISNUMBER(K6)),(K7-K6)*100,"") -> -0.0021773475
A14: 联合 AP 重新积分；语义合并混淆矩阵；实例 mIoU 按 GT 数量加权；覆盖率按 GT 顶点数加权。
A16: 场景等权平均（下表为辅助汇总，不是联合 AP）：
A17: 方法 | B17: 场景数 | C17: 实例 mIoU 每GT最佳 | D17: 实例 AP25 | E17: 实例 AP50 | F17: 实例 AP75 | G17: 语义 mIoU | H17: 语义 AP25 | I17: 语义 AP50 | J17: mAcc | K17: 物体覆盖率 5cm
A18: A ali-my baseline | B18: 8 | C18: =IF(COUNT(逐景主指标!C5,逐景主指标!C8,逐景主指标!C11,逐景主指标!C14,逐景主指标!C17,逐景主指标!C20,逐景主指标!C23,逐景主指标!C26)=8,AVERAGE(逐景主指标!C5,逐景主指标!C8,逐景主指标!C11,逐景主指标!C14,逐景主指标!C17,逐景主指标!C20,逐景主指标!C23,逐景主指标!C26),"") -> 0.35009107 | D18: =IF(COUNT(逐景主指标!D5,逐景主指标!D8,逐景主指标!D11,逐景主指标!D14,逐景主指标!D17,逐景主指标!D20,逐景主指标!D23,逐景主指标!D26)=8,AVERAGE(逐景主指标!D5,逐景主指标!D8,逐景主指标!D11,逐景主指标!D14,逐景主指标!D17,逐景主指标!D20,逐景主指标!D23,逐景主指标!D26),"") -> 0.5169594 | E18: =IF(COUNT(逐景主指标!E5,逐景主指标!E8,逐景主指标!E11,逐景主指标!E14,逐景主指标!E17,逐景主指标!E20,逐景主指标!E23,逐景主指标!E26)=8,AVERAGE(逐景主指标!E5,逐景主指标!E8,逐景主指标!E11,逐景主指标!E14,逐景主指标!E17,逐景主指标!E20,逐景主指标!E23,逐景主指标!E26),"") -> 0.20856623 | F18: =IF(COUNT(逐景主指标!F5,逐景主指标!F8,逐景主指标!F11,逐景主指标!F14,逐景主指标!F17,逐景主指标!F20,逐景主指标!F23,逐景主指标!F26)=8,AVERAGE(逐景主指标!F5,逐景主指标!F8,逐景主指标!F11,逐景主指标!F14,逐景主指标!F17,逐景主指标!F20,逐景主指标!F23,逐景主指标!F26),"") -> 0.028479806 | G18: =IF(COUNT(逐景主指标!G5,逐景主指标!G8,逐景主指标!G11,逐景主指标!G14,逐景主指标!G17,逐景主指标!G20,逐景主指标!G23,逐景主指标!G26)=8,AVERAGE(逐景主指标!G5,逐景主指标!G8,逐景主指标!G11,逐景主指标!G14,逐景主指标!G17,逐景主指标!G20,逐景主指标!G23,逐景主指标!G26),"") -> 0.1426673 | H18: =IF(COUNT(逐景主指标!H5,逐景主指标!H8,逐景主指标!H11,逐景主指标!H14,逐景主指标!H17,逐景主指标!H20,逐景主指标!H23,逐景主指标!H26)=8,AVERAGE(逐景主指标!H5,逐景主指标!H8,逐景主指标!H11,逐景主指标!H14,逐景主指标!H17,逐景主指标!H20,逐景主指标!H23,逐景主指标!H26),"") -> 0.20626763 | I18: =IF(COUNT(逐景主指标!I5,逐景主指标!I8,逐景主指标!I11,逐景主指标!I14,逐景主指标!I17,逐景主指标!I20,逐景主指标!I23,逐景主指标!I26)=8,AVERAGE(逐景主指标!I5,逐景主指标!I8,逐景主指标!I11,逐景主指标!I14,逐景主指标!I17,逐景主指标!I20,逐景主指标!I23,逐景主指标!I26),"") -> 0.16328329 | J18: =IF(COUNT(逐景主指标!J5,逐景主指标!J8,逐景主指标!J11,逐景主指标!J14,逐景主指标!J17,逐景主指标!J20,逐景主指标!J23,逐景主指标!J26)=8,AVERAGE(逐景主指标!J5,逐景主指标!J8,逐景主指标!J11,逐景主指标!J14,逐景主指标!J17,逐景主指标!J20,逐景主指标!J23,逐景主指标!J26),"") -> 0.22719304 | K18: =IF(COUNT(逐景主指标!K5,逐景主指标!K8,逐景主指标!K11,逐景主指标!K14,逐景主指标!K17,逐景主指标!K20,逐景主指标!K23,逐景主指标!K26)=8,AVERAGE(逐景主指标!K5,逐景主指标!K8,逐景主指标!K11,逐景主指标!K14,逐景主指标!K17,逐景主指标!K20,逐景主指标!K23,逐景主指标!K26),"") -> 0.63058095
A19: B baseline＋原图 | B19: 8 | C19: =IF(COUNT(逐景主指标!C6,逐景主指标!C9,逐景主指标!C12,逐景主指标!C15,逐景主指标!C18,逐景主指标!C21,逐景主指标!C24,逐景主指标!C27)=8,AVERAGE(逐景主指标!C6,逐景主指标!C9,逐景主指标!C12,逐景主指标!C15,逐景主指标!C18,逐景主指标!C21,逐景主指标!C24,逐景主指标!C27),"") -> 0.42518686 | D19: =IF(COUNT(逐景主指标!D6,逐景主指标!D9,逐景主指标!D12,逐景主指标!D15,逐景主指标!D18,逐景主指标!D21,逐景主指标!D24,逐景主指标!D27)=8,AVERAGE(逐景主指标!D6,逐景主指标!D9,逐景主指标!D12,逐景主指标!D15,逐景主指标!D18,逐景主指标!D21,逐景主指标!D24,逐景主指标!D27),"") -> 0.6128963 | E19: =IF(COUNT(逐景主指标!E6,逐景主指标!E9,逐景主指标!E12,逐景主指标!E15,逐景主指标!E18,逐景主指标!E21,逐景主指标!E24,逐景主指标!E27)=8,AVERAGE(逐景主指标!E6,逐景主指标!E9,逐景主指标!E12,逐景主指标!E15,逐景主指标!E18,逐景主指标!E21,逐景主指标!E24,逐景主指标!E27),"") -> 0.26062801 | F19: =IF(COUNT(逐景主指标!F6,逐景主指标!F9,逐景主指标!F12,逐景主指标!F15,逐景主指标!F18,逐景主指标!F21,逐景主指标!F24,逐景主指标!F27)=8,AVERAGE(逐景主指标!F6,逐景主指标!F9,逐景主指标!F12,逐景主指标!F15,逐景主指标!F18,逐景主指标!F21,逐景主指标!F24,逐景主指标!F27),"") -> 0.063885213 | G19: =IF(COUNT(逐景主指标!G6,逐景主指标!G9,逐景主指标!G12,逐景主指标!G15,逐景主指标!G18,逐景主指标!G21,逐景主指标!G24,逐景主指标!G27)=8,AVERAGE(逐景主指标!G6,逐景主指标!G9,逐景主指标!G12,逐景主指标!G15,逐景主指标!G18,逐景主指标!G21,逐景主指标!G24,逐景主指标!G27),"") -> 0.1580235 | H19: =IF(COUNT(逐景主指标!H6,逐景主指标!H9,逐景主指标!H12,逐景主指标!H15,逐景主指标!H18,逐景主指标!H21,逐景主指标!H24,逐景主指标!H27)=8,AVERAGE(逐景主指标!H6,逐景主指标!H9,逐景主指标!H12,逐景主指标!H15,逐景主指标!H18,逐景主指标!H21,逐景主指标!H24,逐景主指标!H27),"") -> 0.25081182 | I19: =IF(COUNT(逐景主指标!I6,逐景主指标!I9,逐景主指标!I12,逐景主指标!I15,逐景主指标!I18,逐景主指标!I21,逐景主指标!I24,逐景主指标!I27)=8,AVERAGE(逐景主指标!I6,逐景主指标!I9,逐景主指标!I12,逐景主指标!I15,逐景主指标!I18,逐景主指标!I21,逐景主指标!I24,逐景主指标!I27),"") -> 0.19696916 | J19: =IF(COUNT(逐景主指标!J6,逐景主指标!J9,逐景主指标!J12,逐景主指标!J15,逐景主指标!J18,逐景主指标!J21,逐景主指标!J24,逐景主指标!J27)=8,AVERAGE(逐景主指标!J6,逐景主指标!J9,逐景主指标!J12,逐景主指标!J15,逐景主指标!J18,逐景主指标!J21,逐景主指标!J24,逐景主指标!J27),"") -> 0.25465867 | K19: =IF(COUNT(逐景主指标!K6,逐景主指标!K9,逐景主指标!K12,逐景主指标!K15,逐景主指标!K18,逐景主指标!K21,逐景主指标!K24,逐景主指标!K27)=8,AVERAGE(逐景主指标!K6,逐景主指标!K9,逐景主指标!K12,逐景主指标!K15,逐景主指标!K18,逐景主指标!K21,逐景主指标!K24,逐景主指标!K27),"") -> 0.70270582
A20: C baseline＋原图＋CLIP | B20: 8 | C20: =IF(COUNT(逐景主指标!C7,逐景主指标!C10,逐景主指标!C13,逐景主指标!C16,逐景主指标!C19,逐景主指标!C22,逐景主指标!C25,逐景主指标!C28)=8,AVERAGE(逐景主指标!C7,逐景主指标!C10,逐景主指标!C13,逐景主指标!C16,逐景主指标!C19,逐景主指标!C22,逐景主指标!C25,逐景主指标!C28),"") -> 0.42692327 | D20: =IF(COUNT(逐景主指标!D7,逐景主指标!D10,逐景主指标!D13,逐景主指标!D16,逐景主指标!D19,逐景主指标!D22,逐景主指标!D25,逐景主指标!D28)=8,AVERAGE(逐景主指标!D7,逐景主指标!D10,逐景主指标!D13,逐景主指标!D16,逐景主指标!D19,逐景主指标!D22,逐景主指标!D25,逐景主指标!D28),"") -> 0.61525315 | E20: =IF(COUNT(逐景主指标!E7,逐景主指标!E10,逐景主指标!E13,逐景主指标!E16,逐景主指标!E19,逐景主指标!E22,逐景主指标!E25,逐景主指标!E28)=8,AVERAGE(逐景主指标!E7,逐景主指标!E10,逐景主指标!E13,逐景主指标!E16,逐景主指标!E19,逐景主指标!E22,逐景主指标!E25,逐景主指标!E28),"") -> 0.2730993 | F20: =IF(COUNT(逐景主指标!F7,逐景主指标!F10,逐景主指标!F13,逐景主指标!F16,逐景主指标!F19,逐景主指标!F22,逐景主指标!F25,逐景主指标!F28)=8,AVERAGE(逐景主指标!F7,逐景主指标!F10,逐景主指标!F13,逐景主指标!F16,逐景主指标!F19,逐景主指标!F22,逐景主指标!F25,逐景主指标!F28),"") -> 0.065219526 | G20: =IF(COUNT(逐景主指标!G7,逐景主指标!G10,逐景主指标!G13,逐景主指标!G16,逐景主指标!G19,逐景主指标!G22,逐景主指标!G25,逐景主指标!G28)=8,AVERAGE(逐景主指标!G7,逐景主指标!G10,逐景主指标!G13,逐景主指标!G16,逐景主指标!G19,逐景主指标!G22,逐景主指标!G25,逐景主指标!G28),"") -> 0.13695821 | H20: =IF(COUNT(逐景主指标!H7,逐景主指标!H10,逐景主指标!H13,逐景主指标!H16,逐景主指标!H19,逐景主指标!H22,逐景主指标!H25,逐景主指标!H28)=8,AVERAGE(逐景主指标!H7,逐景主指标!H10,逐景主指标!H13,逐景主指标!H16,逐景主指标!H19,逐景主指标!H22,逐景主指标!H25,逐景主指标!H28),"") -> 0.23858956 | I20: =IF(COUNT(逐景主指标!I7,逐景主指标!I10,逐景主指标!I13,逐景主指标!I16,逐景主指标!I19,逐景主指标!I22,逐景主指标!I25,逐景主指标!I28)=8,AVERAGE(逐景主指标!I7,逐景主指标!I10,逐景主指标!I13,逐景主指标!I16,逐景主指标!I19,逐景主指标!I22,逐景主指标!I25,逐景主指标!I28),"") -> 0.17348021 | J20: =IF(COUNT(逐景主指标!J7,逐景主指标!J10,逐景主指标!J13,逐景主指标!J16,逐景主指标!J19,逐景主指标!J22,逐景主指标!J25,逐景主指标!J28)=8,AVERAGE(逐景主指标!J7,逐景主指标!J10,逐景主指标!J13,逐景主指标!J16,逐景主指标!J19,逐景主指标!J22,逐景主指标!J25,逐景主指标!J28),"") -> 0.2322067 | K20: =IF(COUNT(逐景主指标!K7,逐景主指标!K10,逐景主指标!K13,逐景主指标!K16,逐景主指标!K19,逐景主指标!K22,逐景主指标!K25,逐景主指标!K28)=8,AVERAGE(逐景主指标!K7,逐景主指标!K10,逐景主指标!K13,逐景主指标!K16,逐景主指标!K19,逐景主指标!K22,逐景主指标!K25,逐景主指标!K28),"") -> 0.70268691
A22: 主实例 mIoU 为每 GT 最佳匹配；一对一实例 mIoU、F1、TP/FP/FN 另见“辅助诊断”。
A23: 单次八景实验，不等于统计显著性证明。计时边界不同，不计算方法速度倍率。

Sheet 逐景主指标
A1: 逐景主指标
A2: 每行一组完整场景。A 复用历史地图，B/C 从空地图重新构建，全部关闭 VLM。
A4: 场景 | B4: 方法 | C4: 实例 mIoU 每GT最佳 | D4: 实例 AP25 | E4: 实例 AP50 | F4: 实例 AP75 | G4: 语义 mIoU | H4: 语义 AP25 | I4: 语义 AP50 | J4: mAcc | K4: 物体覆盖率 5cm
A5: room0 | B5: A ali-my baseline | C5: 0.36374026 | D5: 0.42574611 | E5: 0.27164809 | F5: 0.031468293 | G5: 0.15657397 | H5: 0.19227431 | I5: 0.19097222 | J5: 0.25751156 | K5: 0.68032196
A6: room0 | B6: B baseline＋原图 | C6: 0.45626842 | D6: 0.62710387 | E6: 0.30335254 | F6: 0.049570485 | G6: 0.18011402 | H6: 0.28149802 | I6: 0.24503968 | J6: 0.30406979 | K6: 0.79425276
A7: room0 | B7: C baseline＋原图＋CLIP | C7: 0.45668189 | D7: 0.63997405 | E7: 0.31070759 | F7: 0.05040683 | G7: 0.14691108 | H7: 0.24975198 | I7: 0.2281746 | J7: 0.23585465 | K7: 0.79424606
A8: room1 | B8: A ali-my baseline | C8: 0.40577048 | D8: 0.53859015 | E8: 0.16077052 | F8: 0.032055468 | G8: 0.20009318 | H8: 0.30670426 | I8: 0.24310777 | J8: 0.34743291 | K8: 0.76221339
A9: room1 | B9: B baseline＋原图 | C9: 0.41656487 | D9: 0.55762041 | E9: 0.16659114 | F9: 0.036617445 | G9: 0.2256067 | H9: 0.37578321 | I9: 0.20692356 | J9: 0.40114434 | K9: 0.76373666
A10: room1 | B10: C baseline＋原图＋CLIP | C10: 0.41811983 | D10: 0.55762041 | E10: 0.16659114 | F10: 0.036617445 | G10: 0.17923444 | H10: 0.34758772 | I10: 0.19627193 | J10: 0.36420184 | K10: 0.76372578
A11: room2 | B11: A ali-my baseline | C11: 0.30665877 | D11: 0.44686251 | E11: 0.11933365 | F11: 0 | G11: 0.15113352 | H11: 0.18782552 | I11: 0.13541667 | J11: 0.28252882 | K11: 0.64580691
A12: room2 | B12: B baseline＋原图 | C12: 0.38755461 | D12: 0.52429895 | E12: 0.15155845 | F12: 0.0035081054 | G12: 0.17528663 | H12: 0.19140625 | I12: 0.13671875 | J12: 0.29029498 | K12: 0.68160393
A13: room2 | B13: C baseline＋原图＋CLIP | C13: 0.38409573 | D13: 0.50744342 | E13: 0.15315339 | F13: 0.0035081054 | G13: 0.12976942 | H13: 0.21770833 | I13: 0.12916667 | J13: 0.25750865 | K13: 0.68160393
A14: office0 | B14: A ali-my baseline | C14: 0.31335841 | D14: 0.59554482 | E14: 0.19814858 | F14: 0.059265734 | G14: 0.12949414 | H14: 0.25 | I14: 0.15 | J14: 0.23853338 | K14: 0.58543434
A15: office0 | B15: B baseline＋原图 | C15: 0.3408585 | D15: 0.59185614 | E15: 0.1882673 | F15: 0.065708167 | G15: 0.19550293 | H15: 0.325 | I15: 0.225 | J15: 0.27340867 | K15: 0.64396975
A16: office0 | B16: C baseline＋原图＋CLIP | C16: 0.33636552 | D16: 0.56270663 | E16: 0.18983893 | F16: 0.066171654 | G16: 0.14793557 | H16: 0.25 | I16: 0.15 | J16: 0.22751727 | K16: 0.64396173
... A28: office4 | B28: C baseline＋原图＋CLIP | C28: 0.49285988 | D28: 0.76882187 | E28: 0.26120467 | F28: 0.079985524 | G28: 0.14351411 | H28: 0.20769231 | I28: 0.2 | J28: 0.17847455 | K28: 0.72028368

Sheet 改善与退化
A1: 逐景改善与退化
A2: 差值单位：百分点；全部八景均保留。B−A 衡量原图输入，C−B 衡量 CLIP 融合。
A4: 场景 | B4: 比较 | C4: 实例 mIoU 每GT最佳 | D4: 实例 AP25 | E4: 实例 AP50 | F4: 实例 AP75 | G4: 语义 mIoU | H4: 语义 AP25 | I4: 语义 AP50 | J4: mAcc | K4: 物体覆盖率 5cm
A5: room0 | B5: B − A | C5: =IF(AND(ISNUMBER(逐景主指标!C6),ISNUMBER(逐景主指标!C5)),(逐景主指标!C6-逐景主指标!C5)*100,"") -> 9.252816 | D5: =IF(AND(ISNUMBER(逐景主指标!D6),ISNUMBER(逐景主指标!D5)),(逐景主指标!D6-逐景主指标!D5)*100,"") -> 20.135776 | E5: =IF(AND(ISNUMBER(逐景主指标!E6),ISNUMBER(逐景主指标!E5)),(逐景主指标!E6-逐景主指标!E5)*100,"") -> 3.1704456 | F5: =IF(AND(ISNUMBER(逐景主指标!F6),ISNUMBER(逐景主指标!F5)),(逐景主指标!F6-逐景主指标!F5)*100,"") -> 1.8102193 | G5: =IF(AND(ISNUMBER(逐景主指标!G6),ISNUMBER(逐景主指标!G5)),(逐景主指标!G6-逐景主指标!G5)*100,"") -> 2.3540051 | H5: =IF(AND(ISNUMBER(逐景主指标!H6),ISNUMBER(逐景主指标!H5)),(逐景主指标!H6-逐景主指标!H5)*100,"") -> 8.922371 | I5: =IF(AND(ISNUMBER(逐景主指标!I6),ISNUMBER(逐景主指标!I5)),(逐景主指标!I6-逐景主指标!I5)*100,"") -> 5.406746 | J5: =IF(AND(ISNUMBER(逐景主指标!J6),ISNUMBER(逐景主指标!J5)),(逐景主指标!J6-逐景主指标!J5)*100,"") -> 4.655823 | K5: =IF(AND(ISNUMBER(逐景主指标!K6),ISNUMBER(逐景主指标!K5)),(逐景主指标!K6-逐景主指标!K5)*100,"") -> 11.393081
A6: room1 | B6: B − A | C6: =IF(AND(ISNUMBER(逐景主指标!C9),ISNUMBER(逐景主指标!C8)),(逐景主指标!C9-逐景主指标!C8)*100,"") -> 1.0794385 | D6: =IF(AND(ISNUMBER(逐景主指标!D9),ISNUMBER(逐景主指标!D8)),(逐景主指标!D9-逐景主指标!D8)*100,"") -> 1.9030266 | E6: =IF(AND(ISNUMBER(逐景主指标!E9),ISNUMBER(逐景主指标!E8)),(逐景主指标!E9-逐景主指标!E8)*100,"") -> 0.58206189 | F6: =IF(AND(ISNUMBER(逐景主指标!F9),ISNUMBER(逐景主指标!F8)),(逐景主指标!F9-逐景主指标!F8)*100,"") -> 0.4561977 | G6: =IF(AND(ISNUMBER(逐景主指标!G9),ISNUMBER(逐景主指标!G8)),(逐景主指标!G9-逐景主指标!G8)*100,"") -> 2.5513524 | H6: =IF(AND(ISNUMBER(逐景主指标!H9),ISNUMBER(逐景主指标!H8)),(逐景主指标!H9-逐景主指标!H8)*100,"") -> 6.9078947 | I6: =IF(AND(ISNUMBER(逐景主指标!I9),ISNUMBER(逐景主指标!I8)),(逐景主指标!I9-逐景主指标!I8)*100,"") -> -3.6184211 | J6: =IF(AND(ISNUMBER(逐景主指标!J9),ISNUMBER(逐景主指标!J8)),(逐景主指标!J9-逐景主指标!J8)*100,"") -> 5.3711424 | K6: =IF(AND(ISNUMBER(逐景主指标!K9),ISNUMBER(逐景主指标!K8)),(逐景主指标!K9-逐景主指标!K8)*100,"") -> 0.15232734
A7: room2 | B7: B − A | C7: =IF(AND(ISNUMBER(逐景主指标!C12),ISNUMBER(逐景主指标!C11)),(逐景主指标!C12-逐景主指标!C11)*100,"") -> 8.0895842 | D7: =IF(AND(ISNUMBER(逐景主指标!D12),ISNUMBER(逐景主指标!D11)),(逐景主指标!D12-逐景主指标!D11)*100,"") -> 7.743644 | E7: =IF(AND(ISNUMBER(逐景主指标!E12),ISNUMBER(逐景主指标!E11)),(逐景主指标!E12-逐景主指标!E11)*100,"") -> 3.2224797 | F7: =IF(AND(ISNUMBER(逐景主指标!F12),ISNUMBER(逐景主指标!F11)),(逐景主指标!F12-逐景主指标!F11)*100,"") -> 0.35081054 | G7: =IF(AND(ISNUMBER(逐景主指标!G12),ISNUMBER(逐景主指标!G11)),(逐景主指标!G12-逐景主指标!G11)*100,"") -> 2.4153108 | H7: =IF(AND(ISNUMBER(逐景主指标!H12),ISNUMBER(逐景主指标!H11)),(逐景主指标!H12-逐景主指标!H11)*100,"") -> 0.35807292 | I7: =IF(AND(ISNUMBER(逐景主指标!I12),ISNUMBER(逐景主指标!I11)),(逐景主指标!I12-逐景主指标!I11)*100,"") -> 0.13020833 | J7: =IF(AND(ISNUMBER(逐景主指标!J12),ISNUMBER(逐景主指标!J11)),(逐景主指标!J12-逐景主指标!J11)*100,"") -> 0.77661521 | K7: =IF(AND(ISNUMBER(逐景主指标!K12),ISNUMBER(逐景主指标!K11)),(逐景主指标!K12-逐景主指标!K11)*100,"") -> 3.5797021
A8: office0 | B8: B − A | C8: =IF(AND(ISNUMBER(逐景主指标!C15),ISNUMBER(逐景主指标!C14)),(逐景主指标!C15-逐景主指标!C14)*100,"") -> 2.7500091 | D8: =IF(AND(ISNUMBER(逐景主指标!D15),ISNUMBER(逐景主指标!D14)),(逐景主指标!D15-逐景主指标!D14)*100,"") -> -0.36886847 | E8: =IF(AND(ISNUMBER(逐景主指标!E15),ISNUMBER(逐景主指标!E14)),(逐景主指标!E15-逐景主指标!E14)*100,"") -> -0.98812813 | F8: =IF(AND(ISNUMBER(逐景主指标!F15),ISNUMBER(逐景主指标!F14)),(逐景主指标!F15-逐景主指标!F14)*100,"") -> 0.64424326 | G8: =IF(AND(ISNUMBER(逐景主指标!G15),ISNUMBER(逐景主指标!G14)),(逐景主指标!G15-逐景主指标!G14)*100,"") -> 6.6008786 | H8: =IF(AND(ISNUMBER(逐景主指标!H15),ISNUMBER(逐景主指标!H14)),(逐景主指标!H15-逐景主指标!H14)*100,"") -> 7.5 | I8: =IF(AND(ISNUMBER(逐景主指标!I15),ISNUMBER(逐景主指标!I14)),(逐景主指标!I15-逐景主指标!I14)*100,"") -> 7.5 | J8: =IF(AND(ISNUMBER(逐景主指标!J15),ISNUMBER(逐景主指标!J14)),(逐景主指标!J15-逐景主指标!J14)*100,"") -> 3.4875287 | K8: =IF(AND(ISNUMBER(逐景主指标!K15),ISNUMBER(逐景主指标!K14)),(逐景主指标!K15-逐景主指标!K14)*100,"") -> 5.8535411
A9: office1 | B9: B − A | C9: =IF(AND(ISNUMBER(逐景主指标!C18),ISNUMBER(逐景主指标!C17)),(逐景主指标!C18-逐景主指标!C17)*100,"") -> 7.8984853 | D9: =IF(AND(ISNUMBER(逐景主指标!D18),ISNUMBER(逐景主指标!D17)),(逐景主指标!D18-逐景主指标!D17)*100,"") -> 11.28415 | E9: =IF(AND(ISNUMBER(逐景主指标!E18),ISNUMBER(逐景主指标!E17)),(逐景主指标!E18-逐景主指标!E17)*100,"") -> 19.811367 | F9: =IF(AND(ISNUMBER(逐景主指标!F18),ISNUMBER(逐景主指标!F17)),(逐景主指标!F18-逐景主指标!F17)*100,"") -> 12.402958 | G9: =IF(AND(ISNUMBER(逐景主指标!G18),ISNUMBER(逐景主指标!G17)),(逐景主指标!G18-逐景主指标!G17)*100,"") -> -0.14448714 | H9: =IF(AND(ISNUMBER(逐景主指标!H18),ISNUMBER(逐景主指标!H17)),(逐景主指标!H18-逐景主指标!H17)*100,"") -> -1.2254902 | I9: =IF(AND(ISNUMBER(逐景主指标!I18),ISNUMBER(逐景主指标!I17)),(逐景主指标!I18-逐景主指标!I17)*100,"") -> 3.1862745 | J9: =IF(AND(ISNUMBER(逐景主指标!J18),ISNUMBER(逐景主指标!J17)),(逐景主指标!J18-逐景主指标!J17)*100,"") -> -0.069397629 | K9: =IF(AND(ISNUMBER(逐景主指标!K18),ISNUMBER(逐景主指标!K17)),(逐景主指标!K18-逐景主指标!K17)*100,"") -> 12.83269
A10: office2 | B10: B − A | C10: =IF(AND(ISNUMBER(逐景主指标!C21),ISNUMBER(逐景主指标!C20)),(逐景主指标!C21-逐景主指标!C20)*100,"") -> 11.366853 | D10: =IF(AND(ISNUMBER(逐景主指标!D21),ISNUMBER(逐景主指标!D20)),(逐景主指标!D21-逐景主指标!D20)*100,"") -> 14.266539 | E10: =IF(AND(ISNUMBER(逐景主指标!E21),ISNUMBER(逐景主指标!E20)),(逐景主指标!E21-逐景主指标!E20)*100,"") -> 10.780577 | F10: =IF(AND(ISNUMBER(逐景主指标!F21),ISNUMBER(逐景主指标!F20)),(逐景主指标!F21-逐景主指标!F20)*100,"") -> 4.6404941 | G10: =IF(AND(ISNUMBER(逐景主指标!G21),ISNUMBER(逐景主指标!G20)),(逐景主指标!G21-逐景主指标!G20)*100,"") -> 0.60909554 | H10: =IF(AND(ISNUMBER(逐景主指标!H21),ISNUMBER(逐景主指标!H20)),(逐景主指标!H21-逐景主指标!H20)*100,"") -> 2.9411765 | I10: =IF(AND(ISNUMBER(逐景主指标!I21),ISNUMBER(逐景主指标!I20)),(逐景主指标!I21-逐景主指标!I20)*100,"") -> 5.8823529 | J10: =IF(AND(ISNUMBER(逐景主指标!J21),ISNUMBER(逐景主指标!J20)),(逐景主指标!J21-逐景主指标!J20)*100,"") -> 2.384252 | K10: =IF(AND(ISNUMBER(逐景主指标!K21),ISNUMBER(逐景主指标!K20)),(逐景主指标!K21-逐景主指标!K20)*100,"") -> 6.8354221
A11: office3 | B11: B − A | C11: =IF(AND(ISNUMBER(逐景主指标!C24),ISNUMBER(逐景主指标!C23)),(逐景主指标!C24-逐景主指标!C23)*100,"") -> 12.929245 | D11: =IF(AND(ISNUMBER(逐景主指标!D24),ISNUMBER(逐景主指标!D23)),(逐景主指标!D24-逐景主指标!D23)*100,"") -> 19.378024 | E11: =IF(AND(ISNUMBER(逐景主指标!E24),ISNUMBER(逐景主指标!E23)),(逐景主指标!E24-逐景主指标!E23)*100,"") -> 9.9715439 | F11: =IF(AND(ISNUMBER(逐景主指标!F24),ISNUMBER(逐景主指标!F23)),(逐景主指标!F24-逐景主指标!F23)*100,"") -> 2.1234596 | G11: =IF(AND(ISNUMBER(逐景主指标!G24),ISNUMBER(逐景主指标!G23)),(逐景主指标!G24-逐景主指标!G23)*100,"") -> -2.2062211 | H11: =IF(AND(ISNUMBER(逐景主指标!H24),ISNUMBER(逐景主指标!H23)),(逐景主指标!H24-逐景主指标!H23)*100,"") -> 5.615942 | I11: =IF(AND(ISNUMBER(逐景主指标!I24),ISNUMBER(逐景主指标!I23)),(逐景主指标!I24-逐景主指标!I23)*100,"") -> 0 | J11: =IF(AND(ISNUMBER(逐景主指标!J24),ISNUMBER(逐景主指标!J23)),(逐景主指标!J24-逐景主指标!J23)*100,"") -> 4.7655866 | K11: =IF(AND(ISNUMBER(逐景主指标!K24),ISNUMBER(逐景主指标!K23)),(逐景主指标!K24-逐景主指标!K23)*100,"") -> 5.4728726
A12: office4 | B12: B − A | C12: =IF(AND(ISNUMBER(逐景主指标!C27),ISNUMBER(逐景主指标!C26)),(逐景主指标!C27-逐景主指标!C26)*100,"") -> 6.7102017 | D12: =IF(AND(ISNUMBER(逐景主指标!D27),ISNUMBER(逐景主指标!D26)),(逐景主指标!D27-逐景主指标!D26)*100,"") -> 2.4072225 | E12: =IF(AND(ISNUMBER(逐景主指标!E27),ISNUMBER(逐景主指标!E26)),(逐景主指标!E27-逐景主指标!E26)*100,"") -> -4.9009264 | F12: =IF(AND(ISNUMBER(逐景主指标!F27),ISNUMBER(逐景主指标!F26)),(逐景主指标!F27-逐景主指标!F26)*100,"") -> 5.8959426 | G12: =IF(AND(ISNUMBER(逐景主指标!G27),ISNUMBER(逐景主指标!G26)),(逐景主指标!G27-逐景主指标!G26)*100,"") -> 0.10502992 | H12: =IF(AND(ISNUMBER(逐景主指标!H27),ISNUMBER(逐景主指标!H26)),(逐景主指标!H27-逐景主指标!H26)*100,"") -> 4.6153846 | I12: =IF(AND(ISNUMBER(逐景主指标!I27),ISNUMBER(逐景主指标!I26)),(逐景主指标!I27-逐景主指标!I26)*100,"") -> 8.4615385 | J12: =IF(AND(ISNUMBER(逐景主指标!J27),ISNUMBER(逐景主指标!J26)),(逐景主指标!J27-逐景主指标!J26)*100,"") -> 0.60095099 | K12: =IF(AND(ISNUMBER(逐景主指标!K27),ISNUMBER(逐景主指标!K26)),(逐景主指标!K27-逐景主指标!K26)*100,"") -> 11.580261
A13: room0 | B13: C − B | C13: =IF(AND(ISNUMBER(逐景主指标!C7),ISNUMBER(逐景主指标!C6)),(逐景主指标!C7-逐景主指标!C6)*100,"") -> 0.041346607 | D13: =IF(AND(ISNUMBER(逐景主指标!D7),ISNUMBER(逐景主指标!D6)),(逐景主指标!D7-逐景主指标!D6)*100,"") -> 1.2870186 | E13: =IF(AND(ISNUMBER(逐景主指标!E7),ISNUMBER(逐景主指标!E6)),(逐景主指标!E7-逐景主指标!E6)*100,"") -> 0.73550449 | F13: =IF(AND(ISNUMBER(逐景主指标!F7),ISNUMBER(逐景主指标!F6)),(逐景主指标!F7-逐景主指标!F6)*100,"") -> 0.08363448 | G13: =IF(AND(ISNUMBER(逐景主指标!G7),ISNUMBER(逐景主指标!G6)),(逐景主指标!G7-逐景主指标!G6)*100,"") -> -3.3202941 | H13: =IF(AND(ISNUMBER(逐景主指标!H7),ISNUMBER(逐景主指标!H6)),(逐景主指标!H7-逐景主指标!H6)*100,"") -> -3.1746032 | I13: =IF(AND(ISNUMBER(逐景主指标!I7),ISNUMBER(逐景主指标!I6)),(逐景主指标!I7-逐景主指标!I6)*100,"") -> -1.6865079 | J13: =IF(AND(ISNUMBER(逐景主指标!J7),ISNUMBER(逐景主指标!J6)),(逐景主指标!J7-逐景主指标!J6)*100,"") -> -6.8215147 | K13: =IF(AND(ISNUMBER(逐景主指标!K7),ISNUMBER(逐景主指标!K6)),(逐景主指标!K7-逐景主指标!K6)*100,"") -> -0.0006699973
A14: room1 | B14: C − B | C14: =IF(AND(ISNUMBER(逐景主指标!C10),ISNUMBER(逐景主指标!C9)),(逐景主指标!C10-逐景主指标!C9)*100,"") -> 0.15549635 | D14: =IF(AND(ISNUMBER(逐景主指标!D10),ISNUMBER(逐景主指标!D9)),(逐景主指标!D10-逐景主指标!D9)*100,"") -> 0 | E14: =IF(AND(ISNUMBER(逐景主指标!E10),ISNUMBER(逐景主指标!E9)),(逐景主指标!E10-逐景主指标!E9)*100,"") -> 0 | F14: =IF(AND(ISNUMBER(逐景主指标!F10),ISNUMBER(逐景主指标!F9)),(逐景主指标!F10-逐景主指标!F9)*100,"") -> 0 | G14: =IF(AND(ISNUMBER(逐景主指标!G10),ISNUMBER(逐景主指标!G9)),(逐景主指标!G10-逐景主指标!G9)*100,"") -> -4.637226 | H14: =IF(AND(ISNUMBER(逐景主指标!H10),ISNUMBER(逐景主指标!H9)),(逐景主指标!H10-逐景主指标!H9)*100,"") -> -2.8195489 | I14: =IF(AND(ISNUMBER(逐景主指标!I10),ISNUMBER(逐景主指标!I9)),(逐景主指标!I10-逐景主指标!I9)*100,"") -> -1.0651629 | J14: =IF(AND(ISNUMBER(逐景主指标!J10),ISNUMBER(逐景主指标!J9)),(逐景主指标!J10-逐景主指标!J9)*100,"") -> -3.6942499 | K14: =IF(AND(ISNUMBER(逐景主指标!K10),ISNUMBER(逐景主指标!K9)),(逐景主指标!K10-逐景主指标!K9)*100,"") -> -0.0010880525
A15: room2 | B15: C − B | C15: =IF(AND(ISNUMBER(逐景主指标!C13),ISNUMBER(逐景主指标!C12)),(逐景主指标!C13-逐景主指标!C12)*100,"") -> -0.3458883 | D15: =IF(AND(ISNUMBER(逐景主指标!D13),ISNUMBER(逐景主指标!D12)),(逐景主指标!D13-逐景主指标!D12)*100,"") -> -1.6855524 | E15: =IF(AND(ISNUMBER(逐景主指标!E13),ISNUMBER(逐景主指标!E12)),(逐景主指标!E13-逐景主指标!E12)*100,"") -> 0.1594941 | F15: =IF(AND(ISNUMBER(逐景主指标!F13),ISNUMBER(逐景主指标!F12)),(逐景主指标!F13-逐景主指标!F12)*100,"") -> 0 | G15: =IF(AND(ISNUMBER(逐景主指标!G13),ISNUMBER(逐景主指标!G12)),(逐景主指标!G13-逐景主指标!G12)*100,"") -> -4.5517206 | H15: =IF(AND(ISNUMBER(逐景主指标!H13),ISNUMBER(逐景主指标!H12)),(逐景主指标!H13-逐景主指标!H12)*100,"") -> 2.6302083 | I15: =IF(AND(ISNUMBER(逐景主指标!I13),ISNUMBER(逐景主指标!I12)),(逐景主指标!I13-逐景主指标!I12)*100,"") -> -0.75520833 | J15: =IF(AND(ISNUMBER(逐景主指标!J13),ISNUMBER(逐景主指标!J12)),(逐景主指标!J13-逐景主指标!J12)*100,"") -> -3.2786328 | K15: =IF(AND(ISNUMBER(逐景主指标!K13),ISNUMBER(逐景主指标!K12)),(逐景主指标!K13-逐景主指标!K12)*100,"") -> 0
A16: office0 | B16: C − B | C16: =IF(AND(ISNUMBER(逐景主指标!C16),ISNUMBER(逐景主指标!C15)),(逐景主指标!C16-逐景主指标!C15)*100,"") -> -0.44929748 | D16: =IF(AND(ISNUMBER(逐景主指标!D16),ISNUMBER(逐景主指标!D15)),(逐景主指标!D16-逐景主指标!D15)*100,"") -> -2.914951 | E16: =IF(AND(ISNUMBER(逐景主指标!E16),ISNUMBER(逐景主指标!E15)),(逐景主指标!E16-逐景主指标!E15)*100,"") -> 0.15716263 | F16: =IF(AND(ISNUMBER(逐景主指标!F16),ISNUMBER(逐景主指标!F15)),(逐景主指标!F16-逐景主指标!F15)*100,"") -> 0.046348668 | G16: =IF(AND(ISNUMBER(逐景主指标!G16),ISNUMBER(逐景主指标!G15)),(逐景主指标!G16-逐景主指标!G15)*100,"") -> -4.7567358 | H16: =IF(AND(ISNUMBER(逐景主指标!H16),ISNUMBER(逐景主指标!H15)),(逐景主指标!H16-逐景主指标!H15)*100,"") -> -7.5 | I16: =IF(AND(ISNUMBER(逐景主指标!I16),ISNUMBER(逐景主指标!I15)),(逐景主指标!I16-逐景主指标!I15)*100,"") -> -7.5 | J16: =IF(AND(ISNUMBER(逐景主指标!J16),ISNUMBER(逐景主指标!J15)),(逐景主指标!J16-逐景主指标!J15)*100,"") -> -4.5891402 | K16: =IF(AND(ISNUMBER(逐景主指标!K16),ISNUMBER(逐景主指标!K15)),(逐景主指标!K16-逐景主指标!K15)*100,"") -> -0.00080229456
A17: office1 | B17: C − B | C17: =IF(AND(ISNUMBER(逐景主指标!C19),ISNUMBER(逐景主指标!C18)),(逐景主指标!C19-逐景主指标!C18)*100,"") -> -0.00053236617 | D17: =IF(AND(ISNUMBER(逐景主指标!D19),ISNUMBER(逐景主指标!D18)),(逐景主指标!D19-逐景主指标!D18)*100,"") -> 0 | E17: =IF(AND(ISNUMBER(逐景主指标!E19),ISNUMBER(逐景主指标!E18)),(逐景主指标!E19-逐景主指标!E18)*100,"") -> 0 | F17: =IF(AND(ISNUMBER(逐景主指标!F19),ISNUMBER(逐景主指标!F18)),(逐景主指标!F19-逐景主指标!F18)*100,"") -> 0 | G17: =IF(AND(ISNUMBER(逐景主指标!G19),ISNUMBER(逐景主指标!G18)),(逐景主指标!G19-逐景主指标!G18)*100,"") -> 0.34742696 | H17: =IF(AND(ISNUMBER(逐景主指标!H19),ISNUMBER(逐景主指标!H18)),(逐景主指标!H19-逐景主指标!H18)*100,"") -> -3.1862745 | I17: =IF(AND(ISNUMBER(逐景主指标!I19),ISNUMBER(逐景主指标!I18)),(逐景主指标!I19-逐景主指标!I18)*100,"") -> -3.1862745 | J17: =IF(AND(ISNUMBER(逐景主指标!J19),ISNUMBER(逐景主指标!J18)),(逐景主指标!J19-逐景主指标!J18)*100,"") -> -0.00085296576 | K17: =IF(AND(ISNUMBER(逐景主指标!K19),ISNUMBER(逐景主指标!K18)),(逐景主指标!K19-逐景主指标!K18)*100,"") -> 0.0005647197
A18: office2 | B18: C − B | C18: =IF(AND(ISNUMBER(逐景主指标!C22),ISNUMBER(逐景主指标!C21)),(逐景主指标!C22-逐景主指标!C21)*100,"") -> 0.25281432 | D18: =IF(AND(ISNUMBER(逐景主指标!D22),ISNUMBER(逐景主指标!D21)),(逐景主指标!D22-逐景主指标!D21)*100,"") -> 0.21232623 | E18: =IF(AND(ISNUMBER(逐景主指标!E22),ISNUMBER(逐景主指标!E21)),(逐景主指标!E22-逐景主指标!E21)*100,"") -> 2.7666522 | F18: =IF(AND(ISNUMBER(逐景主指标!F22),ISNUMBER(逐景主指标!F21)),(逐景主指标!F22-逐景主指标!F21)*100,"") -> -0.037876202 | G18: =IF(AND(ISNUMBER(逐景主指标!G22),ISNUMBER(逐景主指标!G21)),(逐景主指标!G22-逐景主指标!G21)*100,"") -> -3.4940451 | H18: =IF(AND(ISNUMBER(逐景主指标!H22),ISNUMBER(逐景主指标!H21)),(逐景主指标!H22-逐景主指标!H21)*100,"") -> -3.9215686 | I18: =IF(AND(ISNUMBER(逐景主指标!I22),ISNUMBER(逐景主指标!I21)),(逐景主指标!I22-逐景主指标!I21)*100,"") -> -9.3137255 | J18: =IF(AND(ISNUMBER(逐景主指标!J22),ISNUMBER(逐景主指标!J21)),(逐景主指标!J22-逐景主指标!J21)*100,"") -> -3.0537131 | K18: =IF(AND(ISNUMBER(逐景主指标!K22),ISNUMBER(逐景主指标!K21)),(逐景主指标!K22-逐景主指标!K21)*100,"") -> -0.0039602677
A19: office3 | B19: C − B | C19: =IF(AND(ISNUMBER(逐景主指标!C25),ISNUMBER(逐景主指标!C24)),(逐景主指标!C25-逐景主指标!C24)*100,"") -> 0.98620306 | D19: =IF(AND(ISNUMBER(逐景主指标!D25),ISNUMBER(逐景主指标!D24)),(逐景主指标!D25-逐景主指标!D24)*100,"") -> 1.3209579 | E19: =IF(AND(ISNUMBER(逐景主指标!E25),ISNUMBER(逐景主指标!E24)),(逐景主指标!E25-逐景主指标!E24)*100,"") -> 6.5228502 | F19: =IF(AND(ISNUMBER(逐景主指标!F25),ISNUMBER(逐景主指标!F24)),(逐景主指标!F25-逐景主指标!F24)*100,"") -> 1.0568696 | G19: =IF(AND(ISNUMBER(逐景主指标!G25),ISNUMBER(逐景主指标!G24)),(逐景主指标!G25-逐景主指标!G24)*100,"") -> 2.9985931 | H19: =IF(AND(ISNUMBER(逐景主指标!H25),ISNUMBER(逐景主指标!H24)),(逐景主指标!H25-逐景主指标!H24)*100,"") -> 4.3478261 | I19: =IF(AND(ISNUMBER(逐景主指标!I25),ISNUMBER(逐景主指标!I24)),(逐景主指标!I25-逐景主指标!I24)*100,"") -> 0.86956522 | J19: =IF(AND(ISNUMBER(逐景主指标!J25),ISNUMBER(逐景主指标!J24)),(逐景主指标!J25-逐景主指标!J24)*100,"") -> 2.8580946 | K19: =IF(AND(ISNUMBER(逐景主指标!K25),ISNUMBER(逐景主指标!K24)),(逐景主指标!K25-逐景主指标!K24)*100,"") -> -0.0063976949
A20: office4 | B20: C − B | C20: =IF(AND(ISNUMBER(逐景主指标!C28),ISNUMBER(逐景主指标!C27)),(逐景主指标!C28-逐景主指标!C27)*100,"") -> 0.74898508 | D20: =IF(AND(ISNUMBER(逐景主指标!D28),ISNUMBER(逐景主指标!D27)),(逐景主指标!D28-逐景主指标!D27)*100,"") -> 3.6656851 | E20: =IF(AND(ISNUMBER(逐景主指标!E28),ISNUMBER(逐景主指标!E27)),(逐景主指标!E28-逐景主指标!E27)*100,"") -> -0.36463267 | F20: =IF(AND(ISNUMBER(逐景主指标!F28),ISNUMBER(逐景主指标!F27)),(逐景主指标!F28-逐景主指标!F27)*100,"") -> -0.081525979 | G20: =IF(AND(ISNUMBER(逐景主指标!G28),ISNUMBER(逐景主指标!G27)),(逐景主指标!G28-逐景主指标!G27)*100,"") -> 0.56176759 | H20: =IF(AND(ISNUMBER(逐景主指标!H28),ISNUMBER(逐景主指标!H27)),(逐景主指标!H28-逐景主指标!H27)*100,"") -> 3.8461538 | I20: =IF(AND(ISNUMBER(逐景主指标!I28),ISNUMBER(逐景主指标!I27)),(逐景主指标!I28-逐景主指标!I27)*100,"") -> 3.8461538 | J20: =IF(AND(ISNUMBER(逐景主指标!J28),ISNUMBER(逐景主指标!J27)),(逐景主指标!J28-逐景主指标!J27)*100,"") -> 0.61843249 | K20: =IF(AND(ISNUMBER(逐景主指标!K28),ISNUMBER(逐景主指标!K27)),(逐景主指标!K28-逐景主指标!K27)*100,"") -> -0.0027734305
A23: 比较 | B23: 结果 | C23: 实例 mIoU 每GT最佳 | D23: 实例 AP25 | E23: 实例 AP50 | F23: 实例 AP75 | G23: 语义 mIoU | H23: 语义 AP25 | I23: 语义 AP50 | J23: mAcc | K23: 物体覆盖率 5cm
A24: B − A | B24: 改善场景数 | C24: =IF(COUNT(C5:C12)=8,COUNTIF(C5:C12,">0"),"") -> 8 | D24: =IF(COUNT(D5:D12)=8,COUNTIF(D5:D12,">0"),"") -> 7 | E24: =IF(COUNT(E5:E12)=8,COUNTIF(E5:E12,">0"),"") -> 6 | F24: =IF(COUNT(F5:F12)=8,COUNTIF(F5:F12,">0"),"") -> 8 | G24: =IF(COUNT(G5:G12)=8,COUNTIF(G5:G12,">0"),"") -> 6 | H24: =IF(COUNT(H5:H12)=8,COUNTIF(H5:H12,">0"),"") -> 7 | I24: =IF(COUNT(I5:I12)=8,COUNTIF(I5:I12,">0"),"") -> 6 | J24: =IF(COUNT(J5:J12)=8,COUNTIF(J5:J12,">0"),"") -> 7 | K24: =IF(COUNT(K5:K12)=8,COUNTIF(K5:K12,">0"),"") -> 8
A25: B − A | B25: 退化场景数 | C25: =IF(COUNT(C5:C12)=8,COUNTIF(C5:C12,"<0"),"") -> 0 | D25: =IF(COUNT(D5:D12)=8,COUNTIF(D5:D12,"<0"),"") -> 1 | E25: =IF(COUNT(E5:E12)=8,COUNTIF(E5:E12,"<0"),"") -> 2 | F25: =IF(COUNT(F5:F12)=8,COUNTIF(F5:F12,"<0"),"") -> 0 | G25: =IF(COUNT(G5:G12)=8,COUNTIF(G5:G12,"<0"),"") -> 2 | H25: =IF(COUNT(H5:H12)=8,COUNTIF(H5:H12,"<0"),"") -> 1 | I25: =IF(COUNT(I5:I12)=8,COUNTIF(I5:I12,"<0"),"") -> 1 | J25: =IF(COUNT(J5:J12)=8,COUNTIF(J5:J12,"<0"),"") -> 1 | K25: =IF(COUNT(K5:K12)=8,COUNTIF(K5:K12,"<0"),"") -> 0
A26: B − A | B26: 持平场景数 | C26: =IF(COUNT(C5:C12)=8,COUNTIF(C5:C12,"=0"),"") -> 0 | D26: =IF(COUNT(D5:D12)=8,COUNTIF(D5:D12,"=0"),"") -> 0 | E26: =IF(COUNT(E5:E12)=8,COUNTIF(E5:E12,"=0"),"") -> 0 | F26: =IF(COUNT(F5:F12)=8,COUNTIF(F5:F12,"=0"),"") -> 0 | G26: =IF(COUNT(G5:G12)=8,COUNTIF(G5:G12,"=0"),"") -> 0 | H26: =IF(COUNT(H5:H12)=8,COUNTIF(H5:H12,"=0"),"") -> 0 | I26: =IF(COUNT(I5:I12)=8,COUNTIF(I5:I12,"=0"),"") -> 1 | J26: =IF(COUNT(J5:J12)=8,COUNTIF(J5:J12,"=0"),"") -> 0 | K26: =IF(COUNT(K5:K12)=8,COUNTIF(K5:K12,"=0"),"") -> 0
A27: C − B | B27: 改善场景数 | C27: =IF(COUNT(C13:C20)=8,COUNTIF(C13:C20,">0"),"") -> 5 | D27: =IF(COUNT(D13:D20)=8,COUNTIF(D13:D20,">0"),"") -> 4 | E27: =IF(COUNT(E13:E20)=8,COUNTIF(E13:E20,">0"),"") -> 5 | F27: =IF(COUNT(F13:F20)=8,COUNTIF(F13:F20,">0"),"") -> 3 | G27: =IF(COUNT(G13:G20)=8,COUNTIF(G13:G20,">0"),"") -> 3 | H27: =IF(COUNT(H13:H20)=8,COUNTIF(H13:H20,">0"),"") -> 3 | I27: =IF(COUNT(I13:I20)=8,COUNTIF(I13:I20,">0"),"") -> 2 | J27: =IF(COUNT(J13:J20)=8,COUNTIF(J13:J20,">0"),"") -> 2 | K27: =IF(COUNT(K13:K20)=8,COUNTIF(K13:K20,">0"),"") -> 1
A28: C − B | B28: 退化场景数 | C28: =IF(COUNT(C13:C20)=8,COUNTIF(C13:C20,"<0"),"") -> 3 | D28: =IF(COUNT(D13:D20)=8,COUNTIF(D13:D20,"<0"),"") -> 2 | E28: =IF(COUNT(E13:E20)=8,COUNTIF(E13:E20,"<0"),"") -> 1 | F28: =IF(COUNT(F13:F20)=8,COUNTIF(F13:F20,"<0"),"") -> 2 | G28: =IF(COUNT(G13:G20)=8,COUNTIF(G13:G20,"<0"),"") -> 5 | H28: =IF(COUNT(H13:H20)=8,COUNTIF(H13:H20,"<0"),"") -> 5 | I28: =IF(COUNT(I13:I20)=8,COUNTIF(I13:I20,"<0"),"") -> 6 | J28: =IF(COUNT(J13:J20)=8,COUNTIF(J13:J20,"<0"),"") -> 6 | K28: =IF(COUNT(K13:K20)=8,COUNTIF(K13:K20,"<0"),"") -> 6
A29: C − B | B29: 持平场景数 | C29: =IF(COUNT(C13:C20)=8,COUNTIF(C13:C20,"=0"),"") -> 0 | D29: =IF(COUNT(D13:D20)=8,COUNTIF(D13:D20,"=0"),"") -> 2 | E29: =IF(COUNT(E13:E20)=8,COUNTIF(E13:E20,"=0"),"") -> 2 | F29: =IF(COUNT(F13:F20)=8,COUNTIF(F13:F20,"=0"),"") -> 3 | G29: =IF(COUNT(G13:G20)=8,COUNTIF(G13:G20,"=0"),"") -> 0 | H29: =IF(COUNT(H13:H20)=8,COUNTIF(H13:H20,"=0"),"") -> 0 | I29: =IF(COUNT(I13:I20)=8,COUNTIF(I13:I20,"=0"),"") -> 0 | J29: =IF(COUNT(J13:J20)=8,COUNTIF(J13:J20,"=0"),"") -> 0 | K29: =IF(COUNT(K13:K20)=8,COUNTIF(K13:K20,"=0"),"") -> 1

Sheet 辅助诊断
A1: 辅助诊断
A2: 保留对象数量、覆盖、匹配失败及语义口径诊断；不能替换预先固定的主指标。
A4: 场景 | B4: 组 | C4: 一对一 实例mIoU | D4: F1@0.5 | E4: TP@0.5 | F4: FP@0.5 | G4: FN@0.5 | H4: Precision@0.5 | I4: Recall@0.5 | J4: 语义mIoU union诊断 | K4: 语义面覆盖 | L4: 全网格覆盖 | M4: 地图对象数 | N4: 零支持对象 | O4: 小支持对象
A5: room0 | B5: A | C5: 0.33967118 | D5: 0.42424242 | E5: 28 | F5: 36 | G5: 40 | H5: 0.4375 | I5: 0.41176471 | J5: 0.12177975 | K5: 0.56911322 | L5: 0.57165697 | M5: 72 | N5: 0 | O5: 8
A6: room0 | B6: B | C6: 0.44420651 | D6: 0.45637584 | E6: 34 | F6: 47 | G6: 34 | H6: 0.41975309 | I6: 0.5 | J6: 0.1363025 | K6: 0.70213306 | L6: 0.7044585 | M6: 90 | N6: 0 | O6: 9
A7: room0 | B7: C | C7: 0.4447485 | D7: 0.46258503 | E7: 34 | F7: 45 | G7: 34 | H7: 0.43037975 | I7: 0.5 | J7: 0.11426417 | K7: 0.70214363 | L7: 0.70446897 | M7: 85 | N7: 0 | O7: 6
A8: room1 | B8: A | C8: 0.33780239 | D8: 0.26666667 | E8: 12 | F8: 38 | G8: 28 | H8: 0.24 | I8: 0.3 | J8: 0.18470139 | K8: 0.66279642 | L8: 0.66354305 | M8: 54 | N8: 0 | O8: 4
A9: room1 | B9: B | C9: 0.36747775 | D9: 0.29787234 | E9: 14 | F9: 40 | G9: 26 | H9: 0.25925926 | I9: 0.35 | J9: 0.20053929 | K9: 0.72509055 | L9: 0.72530178 | M9: 57 | N9: 0 | O9: 3
A10: room1 | B10: C | C10: 0.36876191 | D10: 0.31460674 | E10: 14 | F10: 35 | G10: 26 | H10: 0.28571429 | I10: 0.35 | J10: 0.15362952 | K10: 0.72508586 | L10: 0.72529713 | M10: 50 | N10: 0 | O10: 1
A11: room2 | B11: A | C11: 0.24772841 | D11: 0.25263158 | E11: 12 | F11: 36 | G11: 35 | H11: 0.25 | I11: 0.25531915 | J11: 0.11335014 | K11: 0.48804664 | L11: 0.49608856 | M11: 49 | N11: 0 | O11: 1
A12: room2 | B12: B | C12: 0.30331286 | D12: 0.26666667 | E12: 14 | F12: 44 | G12: 33 | H12: 0.24137931 | I12: 0.29787234 | J12: 0.1269317 | K12: 0.6502815 | L12: 0.65570744 | M12: 62 | N12: 0 | O12: 4
A13: room2 | B13: C | C13: 0.29737872 | D13: 0.27184466 | E13: 14 | F13: 42 | G13: 33 | H13: 0.25 | I13: 0.29787234 | J13: 0.097327066 | K13: 0.6502815 | L13: 0.65570744 | M13: 60 | N13: 0 | O13: 4
A14: office0 | B14: A | C14: 0.35399596 | D14: 0.30508475 | E14: 9 | F14: 24 | G14: 17 | H14: 0.27272727 | I14: 0.34615385 | J14: 0.11510591 | K14: 0.46740354 | L14: 0.48833876 | M14: 35 | N14: 0 | O14: 2
A15: office0 | B15: B | C15: 0.39355136 | D15: 0.26666667 | E15: 10 | F15: 39 | G15: 16 | H15: 0.20408163 | I15: 0.38461538 | J15: 0.16179553 | K15: 0.60423109 | L15: 0.61463876 | M15: 49 | N15: 0 | O15: 0
A16: office0 | B16: C | C16: 0.38767491 | D16: 0.28571429 | E16: 10 | F16: 34 | G16: 16 | H16: 0.22727273 | I16: 0.38461538 | J16: 0.13149829 | K16: 0.60422148 | L16: 0.61463028 | M16: 44 | N16: 0 | O16: 0
... A28: office4 | B28: C | C28: 0.50420559 | D28: 0.32098765 | E28: 13 | F28: 39 | G28: 16 | H28: 0.25 | I28: 0.44827586 | J28: 0.099835904 | K28: 0.79350184 | L28: 0.77772586 | M28: 54 | N28: 0 | O28: 2

Sheet 耗时记录
A1: 耗时与运行边界
A2: 秒；空白表示无可靠记录，不是 0。并发运行非独占 GPU benchmark，评估耗时单列。
A4: 场景 | B4: 组 | C4: GPU | D4: 帧数 | E4: VLM调用 | F4: 本次进程 墙钟秒 | G4: bbox准备秒 | H4: 完整端到端秒 | I4: 本次评估秒 | J4: 计时边界
A5: room0 | B5: A | C5: 历史 | D5: 400 | E5: 0 | J5: No verified wall-clock timing retained in map folder; missing, not zero
A6: room0 | B6: B | C6: 6 | D6: 400 | E6: 0 | F6: 2783.4664 | G6: 364.29355 | I6: 29.894534 | J6: online mapping from same-mask cache; bbox CLIP preparation separate; common YOLO/SAM already produced by C and not counted again
A7: room0 | B7: C | C7: 6 | D7: 400 | E7: 0 | F7: 4342.0078 | H7: 4342.0078 | I7: 30.550084 | J7: fresh YOLO+SAM+fused CLIP + online mapping + final audit; concurrent GPU execution
A8: room1 | B8: A | C8: 历史 | D8: 400 | E8: 0 | J8: No verified wall-clock timing retained in map folder; missing, not zero
A9: room1 | B9: B | C9: 6 | D9: 400 | E9: 0 | F9: 1641.34 | G9: 271.20688 | I9: 16.665645 | J9: online mapping from same-mask cache; bbox CLIP preparation separate; common YOLO/SAM already produced by C and not counted again
A10: room1 | B10: C | C10: 6 | D10: 400 | E10: 0 | F10: 2556.929 | H10: 2556.929 | I10: 19.073691 | J10: fresh YOLO+SAM+fused CLIP + online mapping + final audit; concurrent GPU execution
A11: room2 | B11: A | C11: 历史 | D11: 400 | E11: 0 | J11: No verified wall-clock timing retained in map folder; missing, not zero
A12: room2 | B12: B | C12: 1 | D12: 400 | E12: 0 | F12: 1453.6454 | G12: 310.60271 | I12: 17.856298 | J12: online mapping from same-mask cache; bbox CLIP preparation separate; common YOLO/SAM already produced by C and not counted again
A13: room2 | B13: C | C13: 1 | D13: 400 | E13: 0 | F13: 2695.6544 | H13: 2695.6544 | I13: 16.365625 | J13: fresh YOLO+SAM+fused CLIP + online mapping + final audit; concurrent GPU execution
A14: office0 | B14: A | C14: 历史 | D14: 400 | E14: 0 | J14: No verified wall-clock timing retained in map folder; missing, not zero
A15: office0 | B15: B | C15: 7 | D15: 400 | E15: 0 | F15: 1025.7075 | G15: 215.87349 | I15: 15.221138 | J15: online mapping from same-mask cache; bbox CLIP preparation separate; common YOLO/SAM already produced by C and not counted again
A16: office0 | B16: C | C16: 7 | D16: 400 | E16: 0 | F16: 1826.8961 | H16: 1826.8961 | I16: 13.659674 | J16: fresh YOLO+SAM+fused CLIP + online mapping + final audit; concurrent GPU execution
A17: office1 | B17: A | C17: 历史 | D17: 400 | E17: 0 | J17: No verified wall-clock timing retained in map folder; missing, not zero
A18: office1 | B18: B | C18: 1 | D18: 400 | E18: 0 | F18: 908.59869 | G18: 284.36298 | I18: 12.724154 | J18: online mapping from same-mask cache; bbox CLIP preparation separate; common YOLO/SAM already produced by C and not counted again
A19: office1 | B19: C | C19: 1 | D19: 400 | E19: 0 | F19: 2184.0177 | H19: 2184.0177 | I19: 14.362072 | J19: fresh YOLO+SAM+fused CLIP + online mapping + final audit; concurrent GPU execution
A20: office2 | B20: A | C20: 历史 | D20: 400 | E20: 0 | J20: No verified wall-clock timing retained in map folder; missing, not zero
A21: office2 | B21: B | C21: 7 | D21: 400 | E21: 0 | F21: 2044.0626 | G21: 249.03675 | I21: 18.322295 | J21: online mapping from same-mask cache; bbox CLIP preparation separate; common YOLO/SAM already produced by C and not counted again
A22: office2 | B22: C | C22: 7 | D22: 400 | E22: 0 | F22: 3121.9523 | H22: 3121.9523 | I22: 16.960954 | J22: fresh YOLO+SAM+fused CLIP + online mapping + final audit; concurrent GPU execution
A23: office3 | B23: A | C23: 历史 | D23: 400 | E23: 0 | J23: No verified wall-clock timing retained in map folder; missing, not zero
A24: office3 | B24: B | C24: 7 | D24: 400 | E24: 0 | F24: 2243.4297 | G24: 329.32449 | I24: 30.209997 | J24: online mapping from same-mask cache; bbox CLIP preparation separate; common YOLO/SAM already produced by C and not counted again
A25: office3 | B25: C | C25: 7 | D25: 400 | E25: 0 | F25: 2280.9965 | I25: 25.526495 | J25: cached frame-local original-input fused detections + online mapping + final audit; historical detection time unavailable
A26: office4 | B26: A | C26: 历史 | D26: 400 | E26: 0 | J26: No verified wall-clock timing retained in map folder; missing, not zero
A27: office4 | B27: B | C27: 1 | D27: 400 | E27: 0 | F27: 1774.9929 | G27: 245.17428 | I27: 19.030527 | J27: online mapping from same-mask cache; bbox CLIP preparation separate; common YOLO/SAM already produced by C and not counted again
A28: office4 | B28: C | C28: 1 | D28: 400 | E28: 0 | F28: 1888.9935 | I28: 16.739259 | J28: cached frame-local original-input fused detections + online mapping + final audit; historical detection time unavailable

Sheet 结果路径
A1: 可追溯结果路径
A2: 均为服务器绝对路径。地图、统一评估、日志和输入缓存分别保存。
A4: 场景 | B4: 组 | C4: 产物 | D4: 路径 | E4: 地图 SHA256
A5: room0 | B5: A | C5: 最终地图 | D5: /home/chenkejun/beauty/conceptgraphs/data/Replica/room0/exps/ali_my_paper_main_aligned_room0_400f_stride5_bff233f_20260821/pcd_ali_my_paper_main_aligned_room0_400f_stride5_bff233f_20260821.pkl.gz | E5: 64ccdb3b6e77f93fe776b0c62673ac41fe86c831a8937f3284d54decf8004dcb
A6: room0 | B6: A | C6: 统一指标 | D6: /data/chenkejun/paper_ablation_20260911/evaluation/results/A_ali_my_baseline/room0/result.json
A7: room0 | B7: B | C7: 最终地图 | D7: /data/chenkejun/paper_ablation_20260911/runs/B_baseline_original_rgb/Replica/room0/exps/B_baseline_original_rgb_room0/pcd_B_baseline_original_rgb_room0.pkl.gz | E7: 1badfb2f0b5438167a9263bee79b9ecf7ea171d07069bc5747413c23c8c4c0e7
A8: room0 | B8: B | C8: 统一指标 | D8: /data/chenkejun/paper_ablation_20260911/evaluation/results/B_baseline_original_rgb/room0/result.json
A9: room0 | B9: B | C9: 运行日志 | D9: /data/chenkejun/paper_ablation_20260911/logs/B_baseline_original_rgb_room0.log
A10: room0 | B10: B | C10: 检测缓存 | D10: /data/chenkejun/paper_ablation_20260911/runs/B_baseline_original_rgb/Replica/room0/exps/B_baseline_original_rgb_room0_detections
A11: room0 | B11: C | C11: 最终地图 | D11: /data/chenkejun/paper_ablation_20260911/runs/C_baseline_original_rgb_clip/Replica/room0/exps/C_baseline_original_rgb_clip_room0/pcd_C_baseline_original_rgb_clip_room0.pkl.gz | E11: fd2294b20b2b2d78cced215882d054d20acf2ff8bb17bebc7a100f1126e39aeb
A12: room0 | B12: C | C12: 统一指标 | D12: /data/chenkejun/paper_ablation_20260911/evaluation/results/C_baseline_original_rgb_clip/room0/result.json
A13: room0 | B13: C | C13: 运行日志 | D13: /data/chenkejun/paper_ablation_20260911/logs/C_baseline_original_rgb_clip_room0.log
A14: room0 | B14: C | C14: 检测缓存 | D14: /data/chenkejun/paper_ablation_20260911/runs/C_baseline_original_rgb_clip/Replica/room0/exps/C_baseline_original_rgb_clip_room0_detections
A15: room1 | B15: A | C15: 最终地图 | D15: /home/chenkejun/beauty/conceptgraphs/data/Replica/room1/exps/ali_my_paper_main_aligned_room1_400f_stride5_bff233f_20260821/pcd_ali_my_paper_main_aligned_room1_400f_stride5_bff233f_20260821.pkl.gz | E15: d11d531e379da88f1ab3b5e762f06c67e664e48b2e3c612ee29db8025e782e2c
A16: room1 | B16: A | C16: 统一指标 | D16: /data/chenkejun/paper_ablation_20260911/evaluation/results/A_ali_my_baseline/room1/result.json
A17: room1 | B17: B | C17: 最终地图 | D17: /data/chenkejun/paper_ablation_20260911/runs/B_baseline_original_rgb/Replica/room1/exps/B_baseline_original_rgb_room1/pcd_B_baseline_original_rgb_room1.pkl.gz | E17: 8d666a2385ac26f7231ce87b1886c88ff6d625f65fc5ad6157e1e768d1c21723
A18: room1 | B18: B | C18: 统一指标 | D18: /data/chenkejun/paper_ablation_20260911/evaluation/results/B_baseline_original_rgb/room1/result.json
A19: room1 | B19: B | C19: 运行日志 | D19: /data/chenkejun/paper_ablation_20260911/logs/B_baseline_original_rgb_room1.log
A20: room1 | B20: B | C20: 检测缓存 | D20: /data/chenkejun/paper_ablation_20260911/runs/B_baseline_original_rgb/Replica/room1/exps/B_baseline_original_rgb_room1_detections
A21: room1 | B21: C | C21: 最终地图 | D21: /data/chenkejun/paper_ablation_20260911/runs/C_baseline_original_rgb_clip/Replica/room1/exps/C_baseline_original_rgb_clip_room1/pcd_C_baseline_original_rgb_clip_room1.pkl.gz | E21: e0707e1bbe0c2a5d0f67bd06213a941f5f4cf0a71cfc8803922b3eb57632f869
A22: room1 | B22: C | C22: 统一指标 | D22: /data/chenkejun/paper_ablation_20260911/evaluation/results/C_baseline_original_rgb_clip/room1/result.json
A23: room1 | B23: C | C23: 运行日志 | D23: /data/chenkejun/paper_ablation_20260911/logs/C_baseline_original_rgb_clip_room1.log
A24: room1 | B24: C | C24: 检测缓存 | D24: /data/chenkejun/paper_ablation_20260911/runs/C_baseline_original_rgb_clip/Replica/room1/exps/C_baseline_original_rgb_clip_room1_detections
A25: room2 | B25: A | C25: 最终地图 | D25: /home/chenkejun/beauty/conceptgraphs/data/Replica/room2/exps/ali_my_paper_main_aligned_room2_400f_stride5_bff233f_20260821/pcd_ali_my_paper_main_aligned_room2_400f_stride5_bff233f_20260821.pkl.gz | E25: 1dfd9ddc1010d659f7d1453044c2035122094ab10e41148e3727ea8ae9a7dd81
A26: room2 | B26: A | C26: 统一指标 | D26: /data/chenkejun/paper_ablation_20260911/evaluation/results/A_ali_my_baseline/room2/result.json
A27: room2 | B27: B | C27: 最终地图 | D27: /data/chenkejun/paper_ablation_20260911/runs/B_baseline_original_rgb/Replica/room2/exps/B_baseline_original_rgb_room2/pcd_B_baseline_original_rgb_room2.pkl.gz | E27: 1083611a9b7fe6fdce86359057f78c5b8855071c9db2cc52c7f5af7b25e591d4
A28: room2 | B28: B | C28: 统一指标 | D28: /data/chenkejun/paper_ablation_20260911/evaluation/results/B_baseline_original_rgb/room2/result.json
A29: room2 | B29: B | C29: 运行日志 | D29: /data/chenkejun/paper_ablation_20260911/logs/B_baseline_original_rgb_room2.log
A30: room2 | B30: B | C30: 检测缓存 | D30: /data/chenkejun/paper_ablation_20260911/runs/B_baseline_original_rgb/Replica/room2/exps/B_baseline_original_rgb_room2_detections
A31: room2 | B31: C | C31: 最终地图 | D31: /data/chenkejun/paper_ablation_20260911/runs/C_baseline_original_rgb_clip/Replica/room2/exps/C_baseline_original_rgb_clip_room2/pcd_C_baseline_original_rgb_clip_room2.pkl.gz | E31: 851cbfa100c5235e27c0729b1d72d0963cbdffe9fc254b0607023f5339b2060c
A32: room2 | B32: C | C32: 统一指标 | D32: /data/chenkejun/paper_ablation_20260911/evaluation/results/C_baseline_original_rgb_clip/room2/result.json
A33: room2 | B33: C | C33: 运行日志 | D33: /data/chenkejun/paper_ablation_20260911/logs/C_baseline_original_rgb_clip_room2.log
A34: room2 | B34: C | C34: 检测缓存 | D34: /data/chenkejun/paper_ablation_20260911/runs/C_baseline_original_rgb_clip/Replica/room2/exps/C_baseline_original_rgb_clip_room2_detections
A35: office0 | B35: A | C35: 最终地图 | D35: /home/chenkejun/beauty/conceptgraphs/data/Replica/office0/exps/ali_my_paper_main_aligned_office0_400f_stride5_bff233f_20260821/pcd_ali_my_paper_main_aligned_office0_400f_stride5_bff233f_20260821.pkl.gz | E35: 6ff2c625b9f58ba733b4d7af7bafd0098502a93a60a5c63c9f8437fc2fbcf30a
A36: office0 | B36: A | C36: 统一指标 | D36: /data/chenkejun/paper_ablation_20260911/evaluation/results/A_ali_my_baseline/office0/result.json
A37: office0 | B37: B | C37: 最终地图 | D37: /data/chenkejun/paper_ablation_20260911/runs/B_baseline_original_rgb/Replica/office0/exps/B_baseline_original_rgb_office0/pcd_B_baseline_original_rgb_office0.pkl.gz | E37: 0ba60a2a32179d8345edc7bced805f8b4054fea9b2787c8a5add12f87a3afdee
A38: office0 | B38: B | C38: 统一指标 | D38: /data/chenkejun/paper_ablation_20260911/evaluation/results/B_baseline_original_rgb/office0/result.json
A39: office0 | B39: B | C39: 运行日志 | D39: /data/chenkejun/paper_ablation_20260911/logs/B_baseline_original_rgb_office0.log
A40: office0 | B40: B | C40: 检测缓存 | D40: /data/chenkejun/paper_ablation_20260911/runs/B_baseline_original_rgb/Replica/office0/exps/B_baseline_original_rgb_office0_detections
A41: office0 | B41: C | C41: 最终地图 | D41: /data/chenkejun/paper_ablation_20260911/runs/C_baseline_original_rgb_clip/Replica/office0/exps/C_baseline_original_rgb_clip_office0/pcd_C_baseline_original_rgb_clip_office0.pkl.gz | E41: 7cc9304bd693960517417358447a18b954c1622598c8e47427e7d33e0357e097
...

Sheet 实验说明
A1: 实验定义、验证与限制
A2: 用户确认：以 ali-my bff233f 为 baseline，C 全部关闭 VLM；本工作簿不等同于官方 main 论文表。
A4: 项目 | B4: 说明
A5: A 基线 | B5: ali-my bff233ff004939d2ecf4ac5546f87cb7b7b16e60；八景历史地图与统一 v2 结果哈希核验一致后复用。
A6: B 原图输入 | B6: v7_CLIP off，YOLO imgsz=1200，实际张量1216×704，RGB/depth/内参1200×680。使用 bff233f 原 bbox CLIP 函数，无VLM或VLM包含率强制合并。
A7: C 原图＋CLIP | B7: 同B建图规则及逐帧检测；CLIP bbox与softmask各0.5。背景系数0.1，模糊半径3，bbox padding20。VLM全部关闭。
A8: 版本 | B8: v7_CLIP 235e16c995fefb905fd3b21c11ad4fd1e8d3bbe4；冻结代码与配置SHA保存于audit/frozen_code_sha256.json。
A9: 对齐实测 | B9: room0、office2各20采样帧，两组分别与冻结ali-my代码对照。四对逐帧trace、对象成员、点云、包围盒和CLIP特征完全相同，最大差0。旧bbox函数与权重0在232个真实检测上完全一致。
A10: 固定样本 | B10: Replica room0/1/2、office0/1/2/3/4；0:2000:5，每景400帧；不调参，不按结果排除场景。
A11: 在线边界 | B11: B/C都从空地图按帧序列重建。缓存只包含单帧RGB检测及特征，不用旧地图、GT或未来物体状态决定当前更新。B/C框、mask、类别及置信度逐帧SHA一致。
A12: 检测缓存 | B12: room0旧缓存经2026-09-10截图确认清理删除，其余七景仍在。本次前六景已生成新缓存；office3/4复用通过完整RGB哈希和检测合同核验的旧缓存。
A13: 评估协议 | B13: unified_fullmesh_v2_20260910；固定完整GT网格，51语义类、48物体类；已分配预测点的全局精确最近邻，距离严格<5cm才接收。
A14: 实例mIoU | B14: 主值：每GT独立最佳IoU，GT至少10点，不按预测大小过滤。一对一、至少100点的mIoU另作辅助，两者不可混称。
A15: AP | B15: 实例AP25/50/75为类别无关AP；语义AP25/50要求正确语义。AP使用严格IoU>阈值，100点门槛，联合八景重新积分；不是F1。
... A26: 原始指标 | B26: /data/chenkejun/paper_ablation_20260911/evaluation/results/comparison.json
